Workbook

Sheet E-S PDG
B34: 13P091-01-3220-01-309
A43: 309 | B43: 46318 | C43: Updated SQ0-SQ2 documentation (help) | F43: KG
A44: 308 | B44: 45966 | C44: Updated SQ11 documentation (help) | F44: KG
A45: 307 | B45: 45747 | C45: Updated SQ8 | F45: KG
A46: 306 | B46: 45733 | C46: Updated SQ3B | F46: KG
A47: 305 | B47: 45692 | C47: Updated SQ7, SQ8 | F47: KG
A48: 304 | B48: 45684 | C48: Updated SQ9 | F48: KG
A49: 302 | B49: 42182 | C49: Update after starting | F49: AJO
A50: 301 | B50: 42137 | C50: Update for new vlaves FV550 to FV558 | F50: AJO
A51: 300 | B51: 41941 | C51: Update after Uppsala Commitionning | F51: AJO
A52: 207 | B52: 41878 | C52: Update after ACS Tests | F52: AJO
A53: 206 | B53: 41876 | C53: Update for ACS Tests | F53: AJO
A54: 205 | B54: 41856 | C54: Update after Lery Commissioning | F54: BOK | G54: AJO
A55: 204 | B55: 41830 | C55: For Commission at Cryodiffusion | F55: BOK | G55: AJO
A56: VERSION | B56: DATE | D56: MODIFICATION | F56: Dess. Par | G56: Vérifié par | H56: App. Par
G57: Date : | H57: 46318
G58: Page : 0 | H58: Rév. : 307

Sheet Sommaire
B1: SOMMAIRE
B7: Date | G7: Indice | J7: Nom du GRAFCET | R7: Commentaire
Q10: 001 | T10: Cond_pasto2 | AA10: Grafcet conduite pasto 22
Q11: 001 | T11: G7_Cond_pasto | AA11: Conditionneuse pasto 22
Q12: 001 | T12: G7_dem_pasto | AA12: Grafcet démarrage past 22
Q13: 001 | T13: G7_prepa_d_pasto | AA13: grafcet de préparation des solutions de débourrage
Q14: 001 | T14: G7_debour_pasto | AA14: Grafcet du débourrage et de sa distribution
Q15: 001 | T15: G7_prod_pasto | AA15: Grafcet de production pasto 22
Q16: 001 | T16: G7_homo_pasto | AA16: Grafcet homo pasto 22
Q17: 001 | T17: G7_pousse_t1 | AA17: Grafcet de pousse trémie 1
Q18: 001 | T18: G7_pousse_fr2 | AA18: Grafcet de pousse poste fruit 2 (fruit en mélange)
Q19: 001 | T19: G7_POUSSE_AR1
Q20: 001 | T20: G01 | AA20: T01 Dosage d'eau
Q21: 001 | T21: G02 | AA21: T01 Into
Q22: 001 | T22: F04 | AA22: T01 Refroidissement ON
Q23: 001 | T23: F07 | AA23: T01 Introduction MP par dôme

Sheet GXX

Sheet G7_Seq0
B5: FC n°200
B6: DB n°200
R8: He conditioning stop
P11: He conditioning start | AD11: He conditioning start
P12: & Cycle Number > 0 | AD12: & Cycle Number <= 0
AB13: Stop
Q14: Check parameters | Y14: FV011 closed
Q16: Valid or all parameter > 0
Q18: Check equipment | X18: FV011 closed
Q21: Valid ou Equipment OK
Q24: Preliminary | V24: Run P000,
Q25: drain | V25: FV010 & FV502 open; FV011 closed
G29: PT500 >= 5 mbar | P29: PT500 < Low Vacuum (5 mbar)
G30: & Alarm Vacuum timer
E32: X12 | Q32: Time out of | W32: FV011 closed
Q33: Vacuum timer
I36: PT500 > High Vacuum (10 mbar) | Y36: PT500 < High Vacuum (10 mbar)
P38: FV011 closed | Z38: GHe filling | AF38: FV012 & FV502 opened
AF39: FV011 closed
I41: Alarm | Y41: PT500 > High Filling (1080 mbar)
H42: acknowledged | O42: PT500 <= High Filling
O43: & Alarm Pressure timer
Z44: Time out of | AF44: FV011 closed
M45: X14 | Z45: Pressure timer
I47: PT500 < Low Filling | T47: PT500 > Low Filling (1020 mbar) | AH47: PT500 > Low Filling
T48: & Current cycle >= N° of cycle | AH48: & Current cycle < N° of cycle
J50: Pressure alarm | P50: FV011
P51: closed
I53: Alarm acknowledged
M65: ='E-S PDG'!B34 -> 13P091-01-3220-01-309 | AF65: ='E-S PDG'!H57 -> 46318
AF67: PAGE 2

Sheet G7_Seq1
AE4: Updated 2020-11-05
A5: FC n°201
A6: DB n°201
AE7: FV550, FV551, FV553, FV011
P8: He conditioning stop | AE8: are closed when the sequence
AE9: is running
N11: He conditioning start | AB11: He conditioning start
N12: & Cycle Number > 0 | AB12: & Cycle Number <= 0
Z13: Stop
O14: Check parameters | W14: FV011 closed
O16: Valid or all parameter > 0
O18: Check equipment | V18: FV011 closed
O21: Valid or Equipment OK
O24: Preliminary | T24: Run P000 | AG24: HNOSS mode: in steps 4-14:
O25: drain | T25: FV010 & FV100 | AG25: FV101 open, CV552 closed, CV100-
AG26: CV105 and CV550, CV551 set
AG27: according to sequence’s parameters
E29: MKS1 >= 5 mbar | N29: MKS1 < Low Vacuum (5 mbar) | AG29: Cryomodule mode: in steps 4-14:
E30: & Alarm Vacuum timer | AG30: FV101 open, CV101-CV103, CV552
U31: FV101,CV100,CV101,CV102, | AG31: closed,CV100, CV105, CV105 and
C32: X12 | O32: Time out of | U32: CV103,CV104,CV105,CV550, | AG32: CV550,CV551 set according to
O33: Vacuum timer | U33: CV551 open; FV011 closed | AG33: sequence’s parameters
G35: MKS1 > High Vacuum (10 mbar) | W35: MKS1 < High Vacuum (10 mbar)
N38: FV011 closed | X38: GHe filling | AD38: FV012 & FV100 open
AD39: FV011 closed
AD40: FV101,CV100,CV101,CV102,
G41: Alarm | W41: MKS1 > High Filling (1080 mbar)
F42: acknowledged | L42: MKS1 <= High Filling
L43: & Alarm Pressure timer | AD43: FV101,CV100,CV101,CV102,
X44: Time out of | AD44: CV103,CV104,CV105,CV550,
J45: X14 | X45: Pressure timer | AD45: CV551 open; FV011 closed
G47: MKS1 < Low Filling | R47: MKS1 > Low Filling (1020 mbar) | AF47: MKS1 > Low Filling
R48: & Current cycle >= N° of cycle | AF48: & Current cycle < N° of cycle
H50: Pressure alarm | N50: FV011
N51: closed
G53: Alarm acknowledged
K65: ='E-S PDG'!B34 -> 13P091-01-3220-01-309 | AD65: ='E-S PDG'!H57 -> 46318
AD67: PAGE 3

Sheet G7_Seq2
B5: FC n°202
B6: DB n°202
R8: He conditioning stop
P11: He conditioning start | AD11: He conditioning start
P12: & Cycle Number > 0 | AD12: & Cycle Number <= 0
AB13: Stop
Q14: Check parameters | Y14: FV011 closed
Q16: Valid or all parameter > 0
Q18: Check equipment | X18: F>V011 closed
Q21: Valid ou Equipment OK
Q24: Preliminary | V24: Run P000 | AF24: CV301,CV302 opened
Q25: drain | V25: FV010 & FV300 opened | AF25: FV011 closed
G28: PT301 & 302>= 5 mbar
G29: & Alarm Vacuum timer | P29: PT301 & PT302 < Low Vacuum (5 mbar)
E31: X12
Q32: Time out of | W32: CV301,CV302 opened
Q33: Vacuum timer | W33: F>V011 closed
I35: PT301 OR PT302 | Y35: PT301 & PT302 < High Vacuum (10 mbar)
I36: > High Vacuum (10 mbar)
P38: FV011 closed | Z38: GHe filling | AD38: FV012 & FV300 opened
AD39: CV301,CV302 open; FV011 closed
I41: Alarm | O41: PT301 OR PT302 | Y41: PT301 & PT302 > High Filling (1080 mbar)
H42: acknowledged | O42: <= High Filling
O43: & Alarm Pressure timer
Z44: Time out of | AF44: CV301,CV302 opened
M45: X14 | Z45: Pressure timer | AF45: FV011 closed
I47: PT301 & PT302 | T47: PT301 & PT302 > Low Filling | AH47: PT301 & PT302 > Low Filling
I48: < Low Filling (1020 mbar) | T48: & Current cycle >= N° of cycle | AH48: & Current cycle < N° of cycle
J50: Pressure alarm | P50: FV011
P51: closed
I53: Alarm acknowledged
M65: ='E-S PDG'!B34 -> 13P091-01-3220-01-309 | AF65: ='E-S PDG'!H57 -> 46318
AF67: PAGE 4

Sheet G7_Seq3A
B5: FC n°203 | P5: LN2 flow stop
B6: DB n°203
O8: ICB, thermal shield cooling
P11: Check parameters
P13: Valid or all parameter > 0
P15: Check equipment
P18: Valid ou Equipment OK
P20: LN2 flow | V20: LN2 flow request
V21: (up to Linde)
V22: EV400 opened
O24: TT403 Or TT400 < Cool down Tt (200 K)
P30: LN2 flow | V30: EV400 opened | AE30: Heater EH400
O33: TT401B Or TT400 < Low Tt cooling (85 K)
P35: LN2 flow stop
S38: TT401B And TT400 > High Tt cooling (100 K)
M41: LN2 flow in ICB stop
T45: EH400
F48: Gas heating | L48: EH400 running
E51: TT400 > EH400 High limit (30 °C)
F53: Heating stop | L53: EH400 stopped
E56: TT400 < EH400 Low Limit (10 °C)
M65: ='E-S PDG'!B34 -> 13P091-01-3220-01-309 | AF65: ='E-S PDG'!H57 -> 46318
AF67: PAGE 5

Sheet G7_Seq3B
B5: FC n°204
B6: DB n°204
F9: LN2 flow stop | O9: FV400 closed
G10: Run . SQ5
E12: Cryostat, LN2 flow start
F15: Check parameters
F17: Valid or all parameter > 0
F19: Check equipment
F22: Valid ou Equipment OK
F25: LN2 flow | L25: FV400 opened
E29: (TT403 OR TT205 OR TT206) < Cool down Tt (200 K)
F32: LN2 flow | L32: EH200 & | P32: EV201 opened | AC32: EV200 opened
P33: TT216B & TT206 > High Tt cooling (100k) | AC33: TT214B & TT205 > High Tt cooling (100k)
F34: LN2 flow stop | L34: EH 201 | P34: EV201 closed | AC34: EV200 closed
P35: TT216B Or TT206 < Low Tt cooling (85k) | AC35: TT214B Or TT205 < Low Tt cooling (85k)
F36: FV400 opened
E38: LN2 flow stop
R41: EH 200 | AM41: EH201
E45: Gas heating | K45: EH200 running | Z45: Gas heating | AF45: EH201 running
E46: start | Z46: start
D48: TT205 > High Limit (30 °C) | Y48: TT206 > High Limit (30 °C)
E50: Gas heating | K50: EH200 stopped | Z50: Gas heating | AF50: EH201 stopped
E51: stop | Z51: stop
D53: TT205 < Low Limit (10 °C) | Y53: TT206 < Low Limit (10 °C)
M65: ='E-S PDG'!B34 -> 13P091-01-3220-01-309 | AF65: ='E-S PDG'!H57 -> 46318
AF67: PAGE 6

Sheet G7_Seq4
B5: FC n°205
B6: DB n°205
M9: LN2 flow stop
N10: Run . SQ5
L12: Cryostat, LN2 flow start
M15: Check parameters
M17: Valid or all parameter > 0
M19: Check equipment
M22: Valid ou Equipment OK
L26: Coupleur 1 ou Coupleur 2
T27: Coupleur 1 | AC27: Coupleur 2
M29: LN2 flow | Q29: Regulation CV200 | Z29: Regulation CV201 | AI29: EH 202
Q30: TT208 & TIC200 or | Z30: TT210 & TIC201 or | AI30: EH203
Q31: FT200 & FIC200 | Z31: FT201& FIC201 | AI31: FV200
L33: Stopping
C41: Coupleur 1 | X41: Coupleur 2
T42: EH202 | AN42: EH203
F45: Gas heating | L45: EH202 running | AA45: Gas heating | AG45: EH203 running
F46: start | AA46: start
E48: TT211 > High Limit (30 °C) | Z48: TT212 > High Limit (30 °C)
F50: Gas heating | L50: EH202 stopped | AA50: Gas heating | AG50: EH203 stopped
F51: stop | AA51: stop
E53: TT211 < Low Limit (10 °C) | Z53: TT212 < Low Limit (10 °C)
M65: ='E-S PDG'!B34 -> 13P091-01-3220-01-309 | AF65: ='E-S PDG'!H57 -> 46318
AF67: PAGE 7

Sheet G7_Seq5
B5: FC n°206
B6: DB n°206
N10: Start
N13: Check parameters
N15: Valid or all parameter > 0
N17: Check equipment
N20: Valid ou Equipment OK
N23: LHe 4K
N24: Degassing
N26: 4 K vessel order & LT100 < Low Level
AC29: Memo TT101 > 50 K
N30: Cool down | U30: FV500, | AA30: CV100 opened
N31: TL L001 | U31: CV550 opened | AA31: FV101 opened
AC32: Not Memo TT101 > 50 K
M35: TT100 < Filling Tt
N38: Start of 4K vessel | U38: CV100 opened & controlled | AF38: FV500,CV550 opened
N39: filling | V39: PT100>Warning Pressure | AF39: FV101 closed
V40: FT550<Warning Flow
M43: LT100 > High Level
N46: Stop of 4K vessel | U46: FV101 opened
N47: filling | U47: CV550 opened
J53: LT100 < Low Level | V53: Stop of 4k vessel filling sequence
M65: ='E-S PDG'!B34 -> 13P091-01-3220-01-309 | AF65: ='E-S PDG'!H57 -> 46318
AF67: PAGE 8

Sheet G7_Seq6
B5: FC n°207
B6: DB n°207
N9: Lhe level measurement
N10: Run . SQ5
M12: SQ5,Activate
N15: Check parameters
N17: Valid or all parameter > 0
N19: Check equipment
M22: Valid ou Equipment OK
N25: Contrôle Level measurement
M28: Stop
G40: Temperature | N40: No level | Z40: Temperature
G41: control | N41: measurement | Z41: control | AG41: measurement
F44: TT101 < Security Tt (20 K) | Y44: TT113 < Security (20 K)
G46: LT100 measure | Z46: LT101 measure
F49: TT101 > Security Tt (20 K) | Y49: TT113 > Security Tt (20 K)
F50: & LT100 < Security Lt (5%) | Y50: & LT101 < Security Lt (5%)
M65: ='E-S PDG'!B34 -> 13P091-01-3220-01-309 | AF65: ='E-S PDG'!H57 -> 46318
AF67: PAGE 9

Sheet G7_Seq7
B5: FC n°208
B6: DB n°208
N10: Start
N13: Check parameters
N15: Valid or all parameter > 0
N17: Check equipment
N20: (Valid ou Equipment OK) & SQ5
N23: CV550,
N24: CV551,CV552 opened
N26: Cavity 1 ou Cavity2 ou Table ou Shield | AE26: Table
P28: Coupleur 1 | Y28: Coupleur 2 | AH28: Shield
N30: Cooling Cavity 1 | U30: Cooling Cavity 2 | AB30: Table | AE30: Ecran | AH30: CV550,
AH31: CV551,CV552 opened
N35: Stop OR (AutomaticStartSQ8 & SQ8 is running & step > 2)
M65: ='E-S PDG'!B34 -> 13P091-01-3220-01-309 | AF65: ='E-S PDG'!H57 -> 46318
AF67: PAGE 10

Sheet SQ7
B5: FC n°208
B6: DB n°208
G8: FC n°208
G9: DB n°208
F11: Cavity 1 | M11: CV102 opened and controlled | AA11: Cavity 2 | AH11: CV103 opened and controlled
F12: cooling | M12: PT100 < reference P & | AA12: cooling | AH12: PT100 < reference P &
M13: FT552 < reference FT | AH13: FT552 < reference FT
S16: LT101 > 2K High Level
T19: Stop of cavity | AA19: CV102,CV103 closed
T20: filling | AA20: CV104 closed
S23: LT101 < 2K Low Level
T25: Maintain LHe level | AA25: CV104 opened and controlled
AA26: PT100 < reference P &
AA27: FT552 < reference FT
S30: LT101 > 2K High Level
S35: Table or magnetic shield
T37: Cooling | W37: CV101 opened and controlled
T38: table | W38: PT100 < reference P &
W39: FT550 < reference FT
G41: TT107 < TT Equip Cooling & no thermal shield | Y41: TT107 < TT Equip Cooling & thermal shield
H43: Keeping | L43: Regulation CV101 | Z43: Magnetic | AF43: CV101 opened and controlled
H44: cold | L44: TT107 = reference T° | Z44: shield | AF44: PT100 < reference P &
L45: PT100 < reference P | Z45: cooling | AF45: FT550 < reference FT
Y47: TT126 < TT Equip Cooling
Z50: Keeping | AD50: Regulation CV101
Z51: cold | AD51: TT128 = reference T°
AD52: PT100 < reference P
M65: ='E-S PDG'!B34 -> 13P091-01-3220-01-309 | AF65: ='E-S PDG'!H57 -> 46318
AF67: PAGE 11

Sheet G7_Seq8
B5: FC n°209
B6: DB n°209
G9: 4K operation | O9: FV500 closed unless (CV5202 closed and TT500 < 200K)
G10: stop in charge | O10: CV100, CV101, CV102, CV103, CV104, CV105 closed
O11: FV101, CV550, CV551, CV552 open
F13: SQ7.Activate Or SQ9.Activate Or SQ11.Activate Or SQ13.Activate Or Activate SQ12B or4 K operation order
G15: 4K operation
G16: stop
F18: 4 K operation order OR (SQ7 running & AutoStartSQ8 & keeping cold selected equipment & 2K status ON)
G20: Check parameters (CV551 can be 0)
G22: Valid or parameter > 0
G24: Check equipment
G27: Valid or Equipment OK
G30: 4K vessel | N30: CV550,CV552 opened
G31: conditioning
F34: Table or magnetic shield | R34: Table & /Shield | AA34: Shield
G36: Keeping | K36: Regulation CV101 | U36: Regulation CV101
G37: cold | K37: TT107 = reference T° | U37: TT128 = reference T° | AF37: SQ5 | AJ37: 2K
AA38: CV550,CV552 open
F39: 4 K operation stop | AA39: CV551
AE42: 2K
I43: LT101 < LT min
J46: Start of | O46: CV104 opened and controlled
J47: 2 K vessel | O47: PT101 < Warning pressure
J48: filling
I50: LT101 > High Level
J52: Stop of | P52: CV104 closed
J53: 2 K vessel
J54: filling
I56: LT101 < Low Level
M65: ='E-S PDG'!B34 -> 13P091-01-3220-01-309 | AF65: ='E-S PDG'!H57 -> 46318
AF67: PAGE 13

Sheet G7_Seq9
B2: FC n°210 | AM2: 2025-01-27
B3: DB n°210
J6: 4K operation | R6: FV500 closed
J7: stop in charge | R7: CV100, CV101, CV102, CV103, CV104, CV105 closed
R8: FV101, FV552, CV550, CV551, CV552 open
I9: SQ7.Activate OR SQ8.Activate OR SQ11.Activate OR SQ13.Activate OR CM 2K operation order
J11: 2 K
J12: stop
I13: 2 K operation order
J15: Check parameters | R15: Open : | U15: CV552 | X15: FV552
J17: Valid OR all parameter > 0
N19: Check equipment | S19: Open : | V19: CV552 | Y19: FV552
J21: Valid OR Equipment OK
J23: Switch 2K to Keaser Mode
J25: Keaser mode
J27: 2K Pumps Ready | V27: Open : | Y27: CV552 | AB27: FV552
Y28: FV551 | AB28: FV555 | AE28: FV557
J29: Valid (sent by the sequencer program when enabled automatic control of 2K pumps)
J31: Close CV552 | V31: Open : | Y31: FV551 | AB31: FV555 | AE31: FV557
J32: FV552 5sec later
J33: Tps >= 10s
J35: 2 K | O35: CV550 opened | X35: Open : | AA35: FV551
J36: operation | O36: 2K pumps running | AA36: FV555
J37: start | O37: CV551 external control | AA37: FV557
I38: Table OR magnetic shield
R40: Table | Z40: Magnetic Shield
J42: Keeping | N42: Regulation CV101 | V42: Regulation CV101 | AL42: Open : | AO42: FV551
J43: cold | N43: TT107 = reference T° | V43: TT128 = reference T° | AE43: SQ5 | AI43: 2K | AO43: FV555
N44: CV550 opened | AO44: FV557
N45: He pumps start
N46: CV551 external control
I47: Stopping
J49: Pressure | O49: Stopped 2K pumps | AD49: Open : | AG49: FV551
J50: rise | O50: Close CV551 | AG50: FV555
O51: Open FV556 when 2K pumps stopped | AG51: FV557
I52: PT101 > Final Pressure (1000 mbar)
J54: Open CV552 | V54: Open : | Y54: FV551 | AB54: FV557 | AE54: FV555
J55: FV552 5sec before | V55: Open FV556 when 2K pumps stopped
J56: Tps >= 10s
J58: Pumping System Stopped (0 rpm) | W58: Open : | Z58: CV552 | AC58: FV552 | AF58: FV551 | AI58: FV555 | AL58: FV557
...

Sheet G7_Seq10
B5: FC n°211
B6: DB n°211
N9: SHe operation stop | W9: Compressor stopped
N12: Start
N15: Check parameters
N17: Valid or all parameter > 0
N19: Check equipment
N22: Valid ou Equipment OK
N25: Check Coupler | W25: Start Compressor
N28: Coupleur 1 Or Coupleur 2
Q29: Coupleur 1 | Z29: Coupleur 2
N31: Regulation CV301 | W31: Regulation CV302 | AF31: EH301
N32: TT303 = reference T° or | W32: TT304 = reference T° or
N33: FT301 = reference FT | W33: FT302 = reference FT | AF33: EH302
N34: FV301 opened | W34: FV302 opened
N35: Stopping
S39: EH301 | AN39: EH302
E42: Gas heating | K42: EH301 running | Z42: Gas heating | AF42: EH302 running
E43: start | Z43: start
D45: TT307 > High Limit (30 °C) | Y45: TT308 > High Limit (30 °C)
E47: Gas heating | K47: EH301 stopped | Z47: Gas heating | AF47: EH302 stopped
E48: stop | Z48: stop
D50: TT307 < Low Limit (10 °C) | Y50: TT308 < Low Limit (10 °C)
M65: ='E-S PDG'!B34 -> 13P091-01-3220-01-309 | AF65: ='E-S PDG'!H57 -> 46318
AF67: PAGE 15

Sheet G7_Seq11
B5: FC n°212
B6: DB n°212
G9: Standby
G10: operation | N10: Run . SQ5
G11: stopped
F13: Standby 4 K operation start
G16: Check parameters
G18: Valid or all parameter > 0
G20: Check equipment
G23: Valid or Equipment OK
G26: Conditioning | N26: CV550,CV552 opened
N27: CV105 closed
F30: Table And Not Magnetic shield or Magnetic shield | Y30: *)when TIC101 PID is active
M32: Table | W32: Magnetic shield
G33: Keeping | K33: *)Regulation CV101 | U33: *)Regulation CV101 | AE33: LHe Flow
G34: cold | K34: TT107 = reference T° | U34: TT128 = reference T°
U35: CV550,CV552 opened
F36: Stanby 40 K operation stop | U36: CV105 closed
AG40: LHe Flow
J41: (Cavity 1 And TT125 > "LHe low tenperature")
J42: OR (Cavity 2 And TT126 > "LHe low temperature")
J44: LHe flow | O44: CV102 & CV103 opened and controlled
J45: start | O45: PT101 < Warning Pressure
J48: (TT125 < "LHe low temperature" OR NOT Cavity 1)
J49: AND (TT126 < "LHe low temperature" OR NOT Cavity 2)
J51: LHe flow | P51: CV102 & CV103 closed
J52: stop
J55: (Cavity 1 And TT125 > "LHe low temperature")
J56: OR (Cavity 2 And TT126 > "LHe low temperature")
M65: ='E-S PDG'!B34 -> 13P091-01-3220-01-309 | AF65: ='E-S PDG'!H57 -> 46318
AF67: PAGE 16

Sheet G7_Seq12A
B5: FC n°213
B6: DB n°213
N9: Warm-up stop
M12: Warm-up ICB
N15: Check parameters
N17: Valid or all parameter > 0
N19: Check equipment
N22: Valid ou Equipment OK
N25: EH401
N28: TT402 > Warm-up Tt (20°C)
N31: Warm-up end
N34: Fin_Warm-Up
V41: EH401
E43: Thermal shield | L43: EH401 RUN
E44: warm-up start
D46: TT401 > High Limit (20 °C)
E49: Thermal shield | L49: EH401 STOP
E50: warm-up stop
E52: TT401 < Low Limit (0 °C)
M65: ='E-S PDG'!B34 -> 13P091-01-3220-01-309 | AF65: ='E-S PDG'!H57 -> 46318
AF67: PAGE 17

Sheet G7_Seq12B
B5: FC n°214
B6: DB n°214
R7: Warm-up stop
Q10: Warm-up ICB
R13: Check parameters
R15: Valid or all parameter > 0
R17: Check equipment
R20: Valid ou Equipment OK
R22: CV550,CV551,CV552,FV101,CV100 à CV105,
R23: FV200,EV200,EV201,CV200,CV201,FV301,CV302, FV302, CV301
R24: opened
R25: EH100 EH101 EH102 EH103 EH104 EH105 EH106 EH204 EH205
R26: EH206 EH207 EH208 EH300 EH107 EH108
R29: Thermometers > Warm-up Tt (20°C)
R31: Warm-up end
R34: Fin_Warm-Up
M65: ='E-S PDG'!B34 -> 13P091-01-3220-01-309 | AF65: ='E-S PDG'!H57 -> 46318
AF67: PAGE 18

Sheet G7_Seq13
B5: FC n°215
B6: DB n°215
G11: Start Cryostat isolation
G13: Check parameters
G15: Valid or all parameter > 0
G17: Check equipment
G19: Valid ou Equipment OK
G21: Pressure Control
F24: PT300 ou PT301 ou PT302 > She Alarm (6 bars) | T24: PT100 | AH24: Not Cryostat isolation
T25: ou PT101 > He Alarm (1300 mbar)
G26: Pressure Alarm SHe circuit | U26: Pressure Alarm He circuit | AI26: Helium recovry
G28: Ouverture CV550, | U28: Ouverture CV550, | AI28: Ouverture CV550,
G29: CV551, CV552 | U29: CV551, CV552 | AI29: CV551, CV552
F31: A | J31: B | N31: C | T31: A | X31: B | AB31: C | AH31: A | AL31: B
D33: 0 | H33: 4 | L33: 10 | R33: 0 | V33: 4 | Z33: 10 | AF33: 0 | AJ33: 4
C36: A = Sequence Stopping
C37: B = Not Alarm & Cryostat isolation
C38: C = Not Alarm & Not Cryostat isolation
D40: Not Alarm :
E41: X6 = PT300 & PT301 & PT302 < She Pressure (5 bars)
E42: X8 = PT100 & PT101 < He Pressure (1050 mbar)
M65: ='E-S PDG'!B34 -> 13P091-01-3220-01-309 | AF65: ='E-S PDG'!H57 -> 46318
AF67: PAGE 19

Sheet G7_Seq20
B2: FC n°216
B3: DB n°216
F5: Stop
E7: SQ20.Run
F9: Seq 3A
F10: ICB - THERMAL SHIELD COOLING
E12: Seq3A.Run And Conditionning Cryostat | Y12: Seq3A.Run And Not Conditionning Cryostat
F14: Seq 1 | W14: 6
F15: Cryostat, conditioning He Circuit
E16: Seq 1 ok
F18: Testing Couplers
E21: Conditionning Couplers | Y21: Not Conditionning Couplers
F23: Seq 2 | W23: 10
F24: Couplers, conditioning He Circuits
E25: Seq 2 ok
F27: Seq 3B
F28: CRYOSTAT - THERMAL SHIELD COOLING
E29: Seq 3B ok
F31: Seq 5
F32: Test Cooldown cryostat
E34: Seq5 ok And Cryostat cooldown | Y34: Seq5 ok And Not Cryostat cooldown
F36: Seq 7 | W36: 16
F37: Cryostat, Cool Down He Circuits
E38: Seq 7 ok
F40: Operations Control | Q40: 4K : Seq 8
Q41: 2K : Seq 9
F42: (4K or 2K) and SHE : Seq 10 | Q42: Standby : Seq 11
E44: SQ20.Stopping | AA44: Parameters changing
AB46: Change Operations | AM46: 4K : Seq 8
AM47: 2K : Seq 9
F48: Stop Operations | AB48: (4K or 2K) and SHE : Seq 10 | AM48: Standby : Seq 11
F49: Test WarmUp | AA49: Sequences started
E51: Sq8, Sq9, Sq10 & Sq11 Stopped | Y51: 16
E52: And WarmUp
S53: Sq8, Sq9, Sq10 & Sq11 Stopped
F54: Seq 12B | S54: And Not WarmUp
F55: WARM-UP CRYOSTAT | Q55: 22
E56: Seq 12B ok
F58: Test Isolated Cryostat
E61: Isolated Cryostat | S61: Not Isolated Cryostat
...
